<?xml version="1.0" ?>
<sdf version="1.9">
    <model name="my_robot">
        <link name="chassis">
            <pose>0 0 0.1 0 0 0</pose>
            <inertial>
                <mass>5.0</mass>
                <inertia>
                    <ixx>0.1</ixx>
                    <ixy>0</ixy>
                    <ixz>0</ixz>
                    <iyy>0.1</iyy>
                    <iyz>0</iyz>
                    <izz>0.1</izz>
                </inertia>
            </inertial>
            <collision name="collision">
                <geometry>
                    <box>
                        <size>0.5 0.3 0.1</size>
                    </box>
                </geometry>
            </collision>
            <visual name="visual">
                <geometry>
                    <box>
                        <size>0.5 0.3 0.1</size>
                    </box>
                </geometry>
                <material>
                    <diffuse>1 0 0 1</diffuse>
                </material>
            </visual>
        </link>
        <link name="left_wheel">
            <pose>-0.1 0.2 -0.05 0 1.5707 0</pose>
            <inertial>
                <mass>0.5</mass>
                <inertia>
                    <ixx>0.01</ixx>
                    <ixy>0</ixy>
                    <ixz>0</ixz>
                    <iyy>0.01</iyy>
                    <iyz>0</iyz>
                    <izz>0.01</izz>
                </inertia>
            </inertial>
            <collision name="collision">
                <geometry>
                    <cylinder>
                        <radius>0.05</radius>
                        <length>0.02</length>
                    </cylinder>
                </geometry>
            </collision>
            <visual name="visual">
                <geometry>
                    <cylinder>
                        <radius>0.05</radius>
                        <length>0.02</length>
                    </cylinder>
                </geometry>
                <material>
                    <diffuse>0 0 1 1</diffuse>
                </material>
            </visual>
        </link>
        <link name="right_wheel">
            <pose>-0.1 -0.2 -0.05 0 1.5707 0</pose>
            <inertial>
                <mass>0.5</mass>
                <inertia>
                    <ixx>0.01</ixx>
                    <ixy>0</ixy>
                    <ixz>0</ixz>
                    <iyy>0.01</iyy>
                    <iyz>0</iyz>
                    <izz>0.01</izz>
                </inertia>
            </inertial>
            <collision name="collision">
                <geometry>
                    <cylinder>
                        <radius>0.05</radius>
                        <length>0.02</length>
                    </cylinder>
                </geometry>
            </collision>
            <visual name="visual">
                <geometry>
                    <cylinder>
                        <radius>0.05</radius>
                        <length>0.02</length>
                    </cylinder>
                </geometry>
                <material>
                    <diffuse>0 0 1 1</diffuse>
                </material>
            </visual>
        </link>
        <link name="lidar">
            <pose>0 0 0.15 0 0 0</pose>
            <inertial>
                <mass>0.1</mass>
                <inertia>
                    <ixx>0.01</ixx>
                    <ixy>0</ixy>
                    <ixz>0</ixz>
                    <iyy>0.01</iyy>
                    <iyz>0</iyz>
                    <izz>0.01</izz>
                </inertia>
            </inertial>
            <sensor name="lidar_sensor" type="lidar">
                <ray>
                    <scan>
                        <horizontal>
                            <samples>360</samples>
                            <resolution>1</resolution>
                            <min_angle>-3.14159</min_angle>
                            <max_angle>3.14159</max_angle>
                        </horizontal>
                    </scan>
                    <range>
                        <min>0.1</min>
                        <max>10.0</max>
                        <resolution>0.01</resolution>
                    </range>
                </ray>
                <plugin name="lidar_plugin" filename="libgz-sim-sensors-system.so">
                    <gz:system>gz::sim::systems::Sensors</gz:system>
                </plugin>
            </sensor>
        </link>
        <joint name="left_wheel_joint" type="revolute">
            <parent>chassis</parent>
            <child>left_wheel</child>
            <axis>
                <xyz>0 1 0</xyz>
                <limit>
                    <lower>-1e16</lower>
                    <upper>1e16</upper>
                </limit>
            </axis>
        </joint>
        <joint name="right_wheel_joint" type="revolute">
            <parent>chassis</parent>
            <child>right_wheel</child>
            <axis>
                <xyz>0 1 0</xyz>
                <limit>
                    <lower>-1e16</lower>
                    <upper>1e16</upper>
                </limit>
            </axis>
        </joint>
        <joint name="lidar_joint" type="fixed">
            <parent>chassis</parent>
            <child>lidar</child>
        </joint>
        <plugin name="gz::sim::systems::DiffDrive" filename="libgz-sim-diff-drive-system.so">
            <left_joint>left_wheel_joint</left_joint>
            <right_joint>right_wheel_joint</right_joint>
            <wheel_separation>0.4</wheel_separation>
            <wheel_radius>0.05</wheel_radius>
            <odom_publish_frequency>100</odom_publish_frequency>
            <topic>/cmd_vel</topic>
            <odom_topic>/odom</odom_topic>
        </plugin>
    </model>
</sdf>